Workbook

Sheet DCF Analysis
A1: Fastenal Company (FAST)
A3: Discounted Cash Flow Analysis
A5: ($ in millions, except per share data, fiscal year ending March 31)
A7: 1. Main Unlevered Free Cash Flow Build
A9: Line Item | B9: 2023 | C9: 2024 | D9: 2025 | E9: CAGR ('23-'25) | F9: 2026 | G9: 2027 | H9: 2028 | I9: 2029 | J9: 2030 | K9: 2031 | L9: CAGR ('27-'31)
A10: Sales | B10: 7346.7 | C10: 7546 | D10: 8200.5 | E10: =(D10/B10)^(1/2)-1 -> 0.056510977 | F10: =IF('Risk & Credit'!$B$1="Base", 'Bottom-up Revenue'!E12, 'DCF Analysis'!D10* (1 + 'Risk & Credit'!$C$3)) -> 8899.3912 | G10: ='Bottom-up Revenue'!F12 -> 9587.6673 | H10: ='Bottom-up Revenue'!G12 -> 10312.944 | I10: ='Bottom-up Revenue'!H12 -> 11077.192 | J10: ='Bottom-up Revenue'!I12 -> 11882.507 | K10: ='Bottom-up Revenue'!J12 -> 12731.113 | L10: =(K10/F10)^(1/2)-1 -> 0.1960602
A11: % growth | C11: =(C10-B10)/C10 -> 0.026411344 | D11: =(D10-C10)/D10 -> 0.079812207 | F11: =(F10-D10)/D10 -> 0.085225439 | G11: =(G10-F10)/F10 -> 0.077339676 | H11: =(H10-G10)/G10 -> 0.075646797 | I11: =(I10-H10)/H10 -> 0.074105756 | J11: =(J10-I10)/I10 -> 0.072700254 | K11: =(K10-J10)/J10 -> 0.071416439
A12: EBITDA | B12: 1706 | C12: 1685.4 | D12: 1834.9 | E12: =(D12/B12)^(1/2)-1 -> 0.037090574 | F12: =F15+F14 -> 2020.1618 | G12: =G15+G14 -> 2176.4005 | H12: =H15+H14 -> 2341.0382 | I12: =I15+I14 -> 2514.5226 | J12: =J15+J14 -> 2697.329 | K12: =K15+K14 -> 2889.9627 | L12: =(K12/F12)^(1/2)-1 -> 0.1960602
A13: % margin | B13: =B12/B10 -> 0.2322131 | C13: =C12/C10 -> 0.22335012 | D13: =D12/D10 -> 0.22375465 | F13: =F12/F10 -> 0.227 | G13: =G12/G10 -> 0.227 | H13: =H12/H10 -> 0.227 | I13: =I12/I10 -> 0.227 | J13: =J12/J10 -> 0.227 | K13: =K12/K10 -> 0.227
A14: Depreciation & Amortization | B14: 177.3 | C14: 175.4 | D14: 179.2 | F14: =2.2%*F10 -> 195.78661 | G14: =2.2%*G10 -> 210.92868 | H14: =2.2%*H10 -> 226.88476 | I14: =2.2%*I10 -> 243.69823 | J14: =2.2%*J10 -> 261.41515 | K14: =2.2%*K10 -> 280.08449
A15: EBIT | B15: 1528.7 | C15: 1510 | D15: 1655.7 | E15: =(D15/B15)^(1/2)-1 -> 0.040709914 | F15: =F10*F16 -> 1824.3752 | G15: =G10*G16 -> 1965.4718 | H15: =H10*H16 -> 2114.1534 | I15: =I10*I16 -> 2270.8244 | J15: =J10*J16 -> 2435.9139 | K15: =K10*K16 -> 2609.8782 | L15: =(K15/F15)^(1/2)-1 -> 0.1960602
A16: % margin | B16: =B15/B10 -> 0.20807982 | C16: =C15/C10 -> 0.20010602 | D16: =D15/D10 -> 0.20190232 | F16: =IF('Risk & Credit'!$B$1="Base",20.5%,16.5%) -> 0.205 | G16: 0.205 | H16: 0.205 | I16: 0.205 | J16: 0.205 | K16: 0.205
A17: Taxes | B17: 367 | C17: 357.5 | D17: 396.6 | F17: =F15*0.246 -> 448.7963 | G17: =G15*0.246 -> 483.50606 | H17: =H15*0.246 -> 520.08174 | I17: =I15*0.246 -> 558.6228 | J17: =J15*0.246 -> 599.23481 | K17: =K15*0.246 -> 642.03003
A18: EBIAT | B18: =B15-B17 -> 1161.7 | C18: =C15-C17 -> 1152.5 | D18: =D15-D17 -> 1259.1 | E18: =(D18/B18)^(1/2)-1 -> 0.041077636 | F18: =F15-F17 -> 1375.5789 | G18: =G15-G17 -> 1481.9657 | H18: =H15-H17 -> 1594.0717 | I18: =I15-I17 -> 1712.2016 | J18: =J15-J17 -> 1836.6791 | K18: =K15-K17 -> 1967.8481 | L18: =(K18/F18)^(1/2)-1 -> 0.1960602
A19: Plus: Depreciation & Amortization | B19: =B14 -> 177.3 | C19: =C14 -> 175.4 | D19: =D14 -> 179.2 | F19: =F14 -> 195.78661 | G19: =G14 -> 210.92868 | H19: =H14 -> 226.88476 | I19: =I14 -> 243.69823 | J19: =J14 -> 261.41515 | K19: =K14 -> 280.08449
A20: Less: Capital Expenditures | B20: -172.8 | C20: -226.5 | D20: -245.3 | F20: -320 | G20: =-1*(G10*2.6%) -> -249.27935 | H20: =-1*(H10*2.6%) -> -268.13653 | I20: =-1*(I10*2.6%) -> -288.00699 | J20: =-1*(J10*2.6%) -> -308.94518 | K20: =-1*(K10*2.6%) -> -331.00894
A21: Less: Increase in Net Working Capital | B21: 120.1 | C21: =B29-C29 -> -64.866581 | D21: =C29-D29 -> -213.02146 | F21: =D29-F29 -> -227.46956 | G21: =F29-G29 -> -224.01462 | H21: =G29-H29 -> -236.05717 | I21: =H29-I29 -> -248.74152 | J21: =I29-J29 -> -262.10742 | K21: =J29-K29 -> -276.19764
A22: Days Sales Oustanding (DSO) | B22: 55.4 | C22: =B22 -> 55.4 | D22: =$B$22 -> 55.4 | F22: =IF('Risk & Credit'!$B$1="Base", 55.4, 70.4) -> 55.4 | G22: 55.4 | H22: 55.4 | I22: 55.4 | J22: 55.4 | K22: 55.4
A23: Days Inventory Outstanding (DIO) | B23: 141.5 | C23: =$B$23 -> 141.5 | D23: =$B$23 -> 141.5 | F23: =IF('Risk & Credit'!$B$1="Base", 141.5, 161.5) -> 141.5 | G23: 141.5 | H23: 141.5 | I23: 141.5 | J23: 141.5 | K23: 141.5
A24: Days Payable Outstanding (DPO) | B24: 25.6 | C24: =B24 -> 25.6 | D24: =C24 -> 25.6 | F24: =B24 -> 25.6 | G24: =C24 -> 25.6 | H24: =D24 -> 25.6 | I24: =B24 -> 25.6 | J24: =F24 -> 25.6 | K24: =G24 -> 25.6
A25: COGS (% Sales) | B25: =B10*0.547 -> 4018.6449 | C25: =C10*0.547 -> 4127.662 | D25: =D10*0.547 -> 4485.6735 | F25: =F10*54.7% -> 4867.967 | G25: =G10*54.7% -> 5244.454 | H25: =H10*54.7% -> 5641.1801 | I25: =I10*54.7% -> 6059.2241 | J25: =J10*54.7% -> 6499.7312 | K25: =K10*54.7% -> 6963.9188
A26: Accounts receivable | B26: =(B10/365)*B22 -> 1115.0882 | C26: =(C10/365)*C22 -> 1145.3381 | D26: =(D10/365)*D22 -> 1244.6786 | F26: =(F10/365)*F22 -> 1350.7569 | G26: =(G10/365)*G22 -> 1455.224 | H26: =(H10/365)*H22 -> 1565.3071 | I26: =(I10/365)*I22 -> 1681.3053 | J26: =(J10/365)*J22 -> 1803.5366 | K26: =(K10/365)*K22 -> 1932.3388
A27: Accounts Payable | B27: =(B25/365)*B24 -> 281.85564 | C27: =(C25/365)*C24 -> 289.50177 | D27: =(D25/365)*D24 -> 314.61162 | F27: =(F25/365)*F24 -> 341.42453 | G27: =(G25/365)*G24 -> 367.8302 | H27: =(H25/365)*H24 -> 395.65537 | I27: =(I25/365)*I24 -> 424.97571 | J27: =(J25/365)*J24 -> 455.87156 | K27: =(K25/365)*K24 -> 488.42828
A28: Inventory | B28: =(B25/365)*B23 -> 1557.913 | C28: =(C25/365)*C23 -> 1600.1758 | D28: =(D25/365)*D23 -> 1738.9666 | F28: =(F25/365)*F23 -> 1887.1708 | G28: =(G25/365)*G23 -> 2033.1239 | H28: =(H25/365)*H23 -> 2186.9233 | I28: =(I25/365)*I23 -> 2348.9869 | J28: =(J25/365)*J23 -> 2519.7588 | K28: =(K25/365)*K23 -> 2699.711
A29: Total NWC | B29: =B26+B28-B27 -> 2391.1455 | C29: =C26+C28-C27 -> 2456.0121 | D29: =D26+D28-D27 -> 2669.0336 | F29: =F26+F28-F27 -> 2896.5031 | G29: =G26+G28-G27 -> 3120.5178 | H29: =H26+H28-H27 -> 3356.5749 | I29: =I26+I28-I27 -> 3605.3165 | J29: =J26+J28-J27 -> 3867.4239 | K29: =K26+K28-K27 -> 4143.6215
A30: Unlevered Free Cash Flow | B30: =B18+B19+B20+B21 -> 1286.3 | C30: =C18+C19+C20+C21 -> 1036.5334 | D30: =D18+D19+D20+D21 -> 979.97854 | F30: =F18+F19+F20+F21 -> 1023.8959 | G30: =G18+G19+G20+G21 -> 1219.6004 | H30: =H18+H19+H20+H21 -> 1316.7627 | I30: =I18+I19+I20+I21 -> 1419.1513 | J30: =J18+J19+J20+J21 -> 1527.0416 | K30: =K18+K19+K20+K21 -> 1640.726
A31: WACC | B31: 0.09
A32: Discount Period | G32: 0.5 | H32: 1.5 | I32: 2.5 | J32: 3.5 | K32: 4.5
A33: Discount Factor | G33: =1/(1+$B$31)^G32 -> 0.95782629 | H33: =1/(1+$B$31)^H32 -> 0.87873971 | I33: =1/(1+$B$31)^I32 -> 0.80618322 | J33: =1/(1+$B$31)^J32 -> 0.73961763 | K33: =1/(1+$B$31)^K32 -> 0.67854829
A34: Present Value of Free Cash Flow | G34: =G30*G33 -> 1168.1654 | H34: =H30*H33 -> 1157.0917 | I34: =I30*I33 -> 1144.096 | J34: =J30*J33 -> 1129.4269 | K34: =K30*K33 -> 1113.3119
A37: Enterprise Value | E37: Implied Equity Value and Share Price | K37: Implied Perpetuity Growth Rate
A39: Line Item | B39: Value | E39: Line Item | F39: Value | K39: Line Item | L39: Value
A40: Cumulative Present Value of FCF | B40: =SUM(G34:K34) -> 5712.0918 | E40: Enterprise Value | F40: =B48 -> 41009.718 | K40: Terminal Year Free Cash Flow ('31) | L40: =K34 -> 1113.3119
A41: Terminal Value | B41: =18*K12 -> 52019.328 | E41: Less: Total Debt | F41: 120 | K41: WACC | L41: =B31 -> 0.09
A42: Terminal Year EBITDA ('31) | B42: =K12 -> 2889.9627 | E42: Less: Preferred Securities | F42: 0 | K42: Terminal Value | L42: =B41 -> 52019.328
A43: Exit Multiple | B43: 18 | E43: Less: Noncontrolling Interest | F43: 0 | K43: Implied Perpetuity Growth Rate | L43: =(L42*L41-L40)/(L42-L40) -> 0.070098349
A44: Terminal Value | B44: =B42*B43 -> 52019.328 | E44: Plus: Cash and Cash Equivalents | F44: 204.7
A45: Discount Factor | B45: =K33 -> 0.67854829 | E45: Implied Equity Value | F45: =F40-F41+F44 -> 41094.418 | K45: Implied EV/EBITDA
A46: Present Value of Terminal Value | B46: =B44*B45 -> 35297.626 | E46: Fully Diluted Shares Outstanding | F46: 1150.3 | K46: Line Item | L46: Value
A47: % of Enterprise Value | B47: =B46/F40 -> 0.8607137 | E47: Implied Share Price | F47: =F45/F46 -> 35.724957 | K47: Enterprise Value | L47: =F40 -> 41009.718
...

Sheet Risk & Credit
A1: Scenario: | B1: Base | E1: Credit Metrics | Z1: Base
B2: Base | C2: Stress | E2: Interest expense | F2: 6 | Z2: Stress
A3: Revenue GR | B3: 0.115 | C3: -0.15 | E3: Stressed EBIDTA | F3: ='DCF Analysis'!F12 -> 2020.1618
A4: EBIT margin | B4: 0.205 | C4: 0.165 | E4: Interest Coverage Ratio | F4: =F3/F2 -> 336.69363
A5: DSO | B5: 55.4 | C5: 70.4
A6: DIO | B6: 141.5 | C6: 161.5

Sheet Bottom-up Revenue
A1: Operational KPIs
B2: 2023 (Actual) | C2: 2024 (Actual) | D2: 2025E | E2: 2026E | F2: 2027E | G2: 2028E | H2: 2029E | I2: 2030E | J2: 2031E
A3: Public Branches | B3: 1597 | C3: 1499 | D3: =Table4[[#This Row],[Column3]]-50 -> 1449 | E3: =Table4[[#This Row],[Column4]]-50 -> 1399 | F3: =Table4[[#This Row],[Column5]]-50 -> 1349 | G3: =Table4[[#This Row],[Column6]]-50 -> 1299 | H3: =Table4[[#This Row],[Column7]]-50 -> 1249 | I3: =Table4[[#This Row],[Column8]]-50 -> 1199 | J3: =Table4[[#This Row],[Column9]]-50 -> 1149
A4: Revenue per branch ($M) | B4: 2.55 | C4: 2.74 | D4: =Table4[[#This Row],[Column3]]*(1+0.03) -> 2.8222 | E4: =Table4[[#This Row],[Column4]]*(1+0.03) -> 2.906866 | F4: =Table4[[#This Row],[Column5]]*(1+0.03) -> 2.994072 | G4: =Table4[[#This Row],[Column6]]*(1+0.03) -> 3.0838941 | H4: =Table4[[#This Row],[Column7]]*(1+0.03) -> 3.176411 | I4: =Table4[[#This Row],[Column8]]*(1+0.03) -> 3.2717033 | J4: =Table4[[#This Row],[Column9]]*(1+0.03) -> 3.3698544
A5: Onsite locations | B5: 1822 | C5: 2031 | D5: =Table4[[#This Row],[Column3]]+100 -> 2131 | E5: =Table4[[#This Row],[Column4]]+300 -> 2431 | F5: =Table4[[#This Row],[Column5]]+300 -> 2731 | G5: =Table4[[#This Row],[Column6]]+300 -> 3031 | H5: =Table4[[#This Row],[Column7]]+300 -> 3331 | I5: =Table4[[#This Row],[Column8]]+300 -> 3631 | J5: =Table4[[#This Row],[Column9]]+300 -> 3931
A6: Revenue per onsite ($M) | B6: 1.61 | C6: 1.58 | D6: =Table4[[#This Row],[Column3]]*(1+0.03) -> 1.6274 | E6: =Table4[[#This Row],[Column4]]*(1+0.03) -> 1.676222 | F6: =Table4[[#This Row],[Column5]]*(1+0.03) -> 1.7265087 | G6: =Table4[[#This Row],[Column6]]*(1+0.03) -> 1.7783039 | H6: =Table4[[#This Row],[Column7]]*(1+0.03) -> 1.831653 | I6: =Table4[[#This Row],[Column8]]*(1+0.03) -> 1.8866026 | J6: =Table4[[#This Row],[Column9]]*(1+0.03) -> 1.9432007
A7: *reported target of 400 opened onsite locations per year, projected 300 on average
A8: *company stopped reporting numbers beginning of 2025
A9: Total Branch Revenue | B9: =B3*B4 -> 4072.35 | C9: =C3*C4 -> 4107.26 | D9: =D3*D4 -> 4089.3678 | E9: =E3*E4 -> 4066.7055 | F9: =F3*F4 -> 4039.0031 | G9: =G3*G4 -> 4005.9785 | H9: =H3*H4 -> 3967.3373 | I9: =I3*I4 -> 3922.7722 | J9: =J3*J4 -> 3871.9627
A10: Total Onsite Revenue | B10: =B5*B6 -> 2933.42 | C10: =C5*C6 -> 3208.98 | D10: =D5*D6 -> 3467.9894 | E10: =E5*E6 -> 4074.8957 | F10: =F5*F6 -> 4715.0952 | G10: =G5*G6 -> 5390.0392 | H10: =H5*H6 -> 6101.2363 | I10: =I5*I6 -> 6850.2541 | J10: =J5*J6 -> 7638.722
A11: Other/Specialty revnue | B11: 340.9 | C11: 229.7 | D11: 688.9 | E11: =Table5[[#This Row],[Column4]]*1.1 -> 757.79 | F11: =Table5[[#This Row],[Column5]]*1.1 -> 833.569 | G11: =Table5[[#This Row],[Column6]]*1.1 -> 916.9259 | H11: =Table5[[#This Row],[Column7]]*1.1 -> 1008.6185 | I11: =Table5[[#This Row],[Column8]]*1.1 -> 1109.4803 | J11: =Table5[[#This Row],[Column9]]*1.1 -> 1220.4284
A12: Consolidated Net Sales | B12: =B9+B10+B11 -> 7346.67 | C12: =C9+C10+C11 -> 7545.94 | D12: =D9+D10+D11 -> 8246.2572 | E12: =E9+E10+E11 -> 8899.3912 | F12: =F9+F10+F11 -> 9587.6673 | G12: =G9+G10+G11 -> 10312.944 | H12: =H9+H10+H11 -> 11077.192 | I12: =I9+I10+I11 -> 11882.507 | J12: =J9+J10+J11 -> 12731.113
